

====================================================================================================
2020-07-06 11:19:27,238 - error.log - ERROR - 异常发生在：post, 内容：HTTP 请求异常，异常信息
HTTPSConnectionPool(host='api.com', port=443): Read timed out. (read timeout=10)
Traceback (most recent call last):
  File "G:\Python\lib\site-packages\urllib3\contrib\pyopenssl.py", line 485, in wrap_socket
    cnx.do_handshake()
  File "G:\Python\lib\site-packages\OpenSSL\SSL.py", line 1934, in do_handshake
    self._raise_ssl_error(self._ssl, result)
  File "G:\Python\lib\site-packages\OpenSSL\SSL.py", line 1646, in _raise_ssl_error
    raise WantReadError()
OpenSSL.SSL.WantReadError

During handling of the above exception, another exception occurred:

Traceback (most recent call last):
  File "G:\Python\lib\site-packages\urllib3\connectionpool.py", line 376, in _make_request
    self._validate_conn(conn)
  File "G:\Python\lib\site-packages\urllib3\connectionpool.py", line 994, in _validate_conn
    conn.connect()
  File "G:\Python\lib\site-packages\urllib3\connection.py", line 352, in connect
    self.sock = ssl_wrap_socket(
  File "G:\Python\lib\site-packages\urllib3\util\ssl_.py", line 370, in ssl_wrap_socket
    return context.wrap_socket(sock, server_hostname=server_hostname)
  File "G:\Python\lib\site-packages\urllib3\contrib\pyopenssl.py", line 488, in wrap_socket
    raise timeout("select timed out")
socket.timeout: select timed out

During handling of the above exception, another exception occurred:

Traceback (most recent call last):
  File "G:\Python\lib\site-packages\requests\adapters.py", line 439, in send
    resp = conn.urlopen(
  File "G:\Python\lib\site-packages\urllib3\connectionpool.py", line 719, in urlopen
    retries = retries.increment(
  File "G:\Python\lib\site-packages\urllib3\util\retry.py", line 400, in increment
    raise six.reraise(type(error), error, _stacktrace)
  File "G:\Python\lib\site-packages\urllib3\packages\six.py", line 735, in reraise
    raise value
  File "G:\Python\lib\site-packages\urllib3\connectionpool.py", line 665, in urlopen
    httplib_response = self._make_request(
  File "G:\Python\lib\site-packages\urllib3\connectionpool.py", line 379, in _make_request
    self._raise_timeout(err=e, url=url, timeout_value=conn.timeout)
  File "G:\Python\lib\site-packages\urllib3\connectionpool.py", line 330, in _raise_timeout
    raise ReadTimeoutError(
urllib3.exceptions.ReadTimeoutError: HTTPSConnectionPool(host='api.com', port=443): Read timed out. (read timeout=10)

During handling of the above exception, another exception occurred:

Traceback (most recent call last):
  File "G:/Python_scripts/Python_Advanced/myRequests.py", line 28, in post
    response = self.session.post(self.url, data=bodyData, json=bodyJson, timeout=self.timeout, **kwargs)
  File "G:\Python\lib\site-packages\requests\sessions.py", line 578, in post
    return self.request('POST', url, data=data, json=json, **kwargs)
  File "G:\Python\lib\site-packages\requests\sessions.py", line 530, in request
    resp = self.send(prep, **send_kwargs)
  File "G:\Python\lib\site-packages\requests\sessions.py", line 643, in send
    r = adapter.send(request, **kwargs)
  File "G:\Python\lib\site-packages\requests\adapters.py", line 529, in send
    raise ReadTimeout(e, request=request)
requests.exceptions.ReadTimeout: HTTPSConnectionPool(host='api.com', port=443): Read timed out. (read timeout=10)

During handling of the above exception, another exception occurred:

Traceback (most recent call last):
  File "G:\Python_scripts\Python_Advanced\myLog.py", line 33, in wrapper
    func(*args, **kwargs)
  File "G:/Python_scripts/Python_Advanced/myRequests.py", line 33, in post
    raise Exception("HTTP 请求异常，异常信息\n%s" %self.errorMsg)
Exception: HTTP 请求异常，异常信息
HTTPSConnectionPool(host='api.com', port=443): Read timed out. (read timeout=10)


====================================================================================================
2020-07-06 11:26:21,956 - error.log - ERROR - 异常发生在：foo, 内容：name 'a' is not defined
Traceback (most recent call last):
  File "G:/Python_scripts/Python_Advanced/myLog.py", line 33, in wrapper
    func(*args, **kwargs)
  File "G:/Python_scripts/Python_Advanced/myLog.py", line 47, in foo
    print(a)
NameError: name 'a' is not defined
